Workbook

Sheet Summary
A1: StockMock Iron Condor report — data validation
A2: Source: user-uploaded StockMock export (Simulator Rule sheet). Blue = values copied from report; black = recomputed by formula.
A4: Metric | B4: Reported (StockMock) | C4: Recomputed (67 closed trades) | D4: Match?
A5: Total Trades | B5: 67 | C5: =COUNT(Trades!AB2:AB68) -> 67 | D5: =IF(ABS(B5-C5)<=IF(ABS(B5)<1,0.01,1),"OK","DIFF") -> OK
A6: Overall Profit ₹ | B6: 35258 | C6: =SUM(Trades!AB2:AB68) -> 35258 | D6: =IF(ABS(B6-C6)<=IF(ABS(B6)<1,0.01,1),"OK","DIFF") -> OK
A7: Avg Trade Profit ₹ | B7: 526 | C7: =AVERAGE(Trades!AB2:AB68) -> 526.23881 | D7: =IF(ABS(B7-C7)<=IF(ABS(B7)<1,0.01,1),"OK","DIFF") -> OK
A8: Max Profit ₹ | B8: 4605 | C8: =MAX(Trades!AB2:AB68) -> 4605 | D8: =IF(ABS(B8-C8)<=IF(ABS(B8)<1,0.01,1),"OK","DIFF") -> OK
A9: Max Loss ₹ | B9: -5981 | C9: =MIN(Trades!AB2:AB68) -> -5981 | D9: =IF(ABS(B9-C9)<=IF(ABS(B9)<1,0.01,1),"OK","DIFF") -> OK
A10: Win % | B10: 0.63 | C10: =COUNTIF(Trades!AB2:AB68,">0")/COUNT(Trades!AB2:AB68) -> 0.62686567 | D10: =IF(ABS(B10-C10)<=IF(ABS(B10)<1,0.01,1),"OK","DIFF") -> OK
A11: Winning trades | B11: 42 | C11: =COUNTIF(Trades!AB2:AB68,">0") -> 42 | D11: =IF(ABS(B11-C11)<=IF(ABS(B11)<1,0.01,1),"OK","DIFF") -> OK
A12: Losing trades | B12: 25 | C12: =COUNTIF(Trades!AB2:AB68,"<=0") -> 25 | D12: =IF(ABS(B12-C12)<=IF(ABS(B12)<1,0.01,1),"OK","DIFF") -> OK
A13: Avg Profit on Win ₹ | B13: 2466 | C13: =AVERAGEIF(Trades!AB2:AB68,">0") -> 2466.381 | D13: =IF(ABS(B13-C13)<=IF(ABS(B13)<1,0.01,1),"OK","DIFF") -> OK
A14: Avg Loss on Loss ₹ | B14: -2733 | C14: =AVERAGEIF(Trades!AB2:AB68,"<=0") -> -2733.2 | D14: =IF(ABS(B14-C14)<=IF(ABS(B14)<1,0.01,1),"OK","DIFF") -> OK
A15: Max Drawdown ₹ | B15: -11120 | C15: =MIN(Trades!AL2:AL68) -> -11120 | D15: =IF(ABS(B15-C15)<=IF(ABS(B15)<1,0.01,1),"OK","DIFF") -> OK
A16: Max win streak | B16: 9 | C16: =MAX(Trades!AM2:AM68) -> 9 | D16: =IF(ABS(B16-C16)<=IF(ABS(B16)<1,0.01,1),"OK","DIFF") -> OK
A17: Max loss streak | B17: 3 | C17: =MAX(Trades!AN2:AN68) -> 3 | D17: =IF(ABS(B17-C17)<=IF(ABS(B17)<1,0.01,1),"OK","DIFF") -> OK
A18: Win/loss trade counts are parsed from the "63% (42)" / "37% (25)" text. Avg-trade tolerance ±₹1 because StockMock rounds to whole rupees.
A20: Additional metrics (not in StockMock report)
A21: Total P&L in points | B21: =SUM(Trades!Y2:Y68) -> 531.1
A22: Profit factor | B22: =SUMIF(Trades!AB2:AB68,">0")/-SUMIF(Trades!AB2:AB68,"<0") -> 1.5159959
A23: Avg net credit (pts) | B23: =AVERAGE(Trades!W2:W68) -> 103.48731
A24: Avg max theoretical loss (pts) = 200 − credit | B24: =200-AVERAGE(Trades!W2:W68) -> 96.512687
A25: Exits: TARGET | B25: =COUNTIF(Trades!AG2:AG68,"TARGET") -> 17
A26: Exits: STOPLOSS | B26: =COUNTIF(Trades!AG2:AG68,"STOPLOSS") -> 3
A27: Exits: TIME (15 DTE / prior trading day) | B27: =COUNTIF(Trades!AG2:AG68,"TIME") -> 46
A28: Exits: MANUAL | B28: =COUNTIF(Trades!AG2:AG68,"MANUAL") -> 1
A29: Cycles skipped (Apr-2026, no StockMock data) | B29: 1
A30: Trades entered while previous still open | B30: =COUNTIF(Trades!AI2:AI68,"YES") -> 32
A31: Leg rows failing Diff check | B31: =COUNTIF(Legs!O2:O269,"MISMATCH") -> 0
A32: Leg rows failing Profit check | B32: =COUNTIF(Legs!P2:P269,"MISMATCH") -> 0
A33: Trades with P&L recon diff > ₹4 | B33: =SUMPRODUCT(--(ABS(Trades!AC2:AC68)>4)) -> 0
A34: Trades with wing ≠ 200 | B34: =SUMPRODUCT(--((Trades!M2:M68<>200)+(Trades!N2:N68<>200)>0)) -> 0
A35: Trades with entry DTE outside 42–45 | B35: =SUMPRODUCT(--((Trades!F2:F68<42)+(Trades!F2:F68>45)>0)) -> 0

Sheet Findings
A1: # | B1: Severity | C1: Area | D1: Finding | E1: Impact on automation
A2: 1 | B2: INFO | C2: Headline stats | D2: All 67 trades are closed. StockMock headline stats reconcile exactly (₹35,258, 42W/25L, MDD -₹11,120). Trade 67 has exit prices but a blank Exit Time cell in the export. | E2: Treat blank exit time with exit prices as CLOSED; 17-Aug-26 trade exit = 11-Sep-26 (user-confirmed).
A3: 2 | B3: MEDIUM | C3: Manual exit | D3: Trade 23 (14-Nov-22) was exited manually at 17 DTE (user-confirmed). 15 DTE (14-Dec-22) was a Wednesday trading day, not a weekend. | E3: Rule-based engine will hold to 14-Dec-22 (or earlier TP/SL); tag as expected mismatch in reconciliation.
A4: 3 | B4: MEDIUM | C4: Exit rule | D4: Trade 62 (15 DTE on a Sunday → 17 DTE) and trade 67 (15 DTE on the 14-Sep-26 holiday → 18 DTE) exited on the previous trading day. | E4: Time exit = last trading day on or before (expiry − 15 calendar days). Needs NSE trading calendar.
A5: 4 | B5: MEDIUM | C5: Skipped cycle | D5: No trade for the April-2026 expiry — StockMock lacked proper strike data (user-confirmed). | E5: Engine skips this cycle and logs it; exclude from comparisons.
A6: 5 | B6: HIGH | C6: Concurrency | D6: 32 of 66 new trades were entered before the previous trade exited. Two condors are often open together. | E6: Engine must support ≥2 simultaneous positions; risk and margin budgets must assume 2 condors.
A7: 6 | B7: MEDIUM | C7: Stop-loss | D7: SL at 100% of credit ≈ structure max loss (credit ≈103 pts, wing 200 → max ≈97 pts). One SL overshot to -112% on a daily-only check. | E7: Size on max loss (wing − credit), not on SL.
A8: 7 | B8: INFO | C8: Lot size | D8: Qty per lot: 50 (to Jan-25 expiry), 75 (Feb-25 to Dec-25), 65 (Jan-26 onward). Sizing = 1 lot at each period's lot size (user decision). | E8: Engine needs a lot-size lookup by expiry; report points and rupees.
A9: 8 | B9: MEDIUM | C9: Delta column | D9: Deltas are position deltas at exit, not entry deltas. 30-delta selection cannot be verified from this file. | E9: Use report strikes as given (per spec).
A10: 9 | B10: LOW | C10: Entry timing | D10: Entries are Mondays (Tuesday when Monday was a holiday: 16-Aug-22, 15-Apr-25). Entry DTE 42–45. | E10: Replay uses report dates.
A11: 10 | B11: LOW | C11: Format | D11: Numbers stored as text; timestamps have no year; leg order varies; one blank exit time. | E11: Parser must cast types, infer year from block header, identify legs by side+type.
A12: 11 | B12: INFO | C12: Arithmetic | D12: All 268 legs and 67 trade P&Ls reconcile; all wings 200; all entries 11:16, exits 15:16; legs exit together. | E12: File is usable as the reference dataset.
A13: 12 | B13: INFO | C13: Costs | D13: Report P&L excludes brokerage, taxes and slippage. | E13: Automation reports gross and net P&L.

Sheet Trades
A1: Trade # | B1: Status | C1: Entry DT | D1: Exit DT | E1: Expiry | F1: Entry DTE | G1: Exit DTE | H1: Qty | I1: Sell CE | J1: Buy CE | K1: Sell PE | L1: Buy PE | M1: CE wing | N1: PE wing | O1: SC entry | P1: BC entry | Q1: SP entry | R1: BP entry | S1: SC exit | T1: BC exit | U1: SP exit | V1: BP exit | W1: Net credit (pts) | X1: Exit value (pts) | Y1: P&L (pts) | Z1: P&L % credit | AA1: P&L ₹ (calc) | AB1: P&L ₹ (reported) | AC1: Recon diff ₹ | AD1: TP level (pts) | AE1: SL level (pts) | AF1: Exit reason (rule) | AG1: Exit type (confirmed) | AH1: Explanation / flag | AI1: Overlaps prev trade? | AJ1: Cum P&L ₹ | AK1: Peak ₹ | AL1: Drawdown ₹ | AM1: Win streak | AN1: Loss streak
A2: 1 | B2: =IF(D2="","OPEN","CLOSED") -> CLOSED | C2: 44207.469 | D2: 44237.636 | E2: 44252 | F2: =INT(E2)-INT(C2) -> 45 | G2: =IF(D2="","",INT(E2)-INT(D2)) -> 15 | H2: 50 | I2: 15100 | J2: 15300 | K2: 13800 | L2: 13600 | M2: =J2-I2 -> 200 | N2: =K2-L2 -> 200 | O2: 199.1 | P2: 147.3 | Q2: 217.4 | R2: 168.7 | S2: 256.2 | T2: 155.3 | U2: 22.6 | V2: 16.6 | W2: =O2+Q2-P2-R2 -> 100.5 | X2: =S2+U2-T2-V2 -> 106.9 | Y2: =W2-X2 -> -6.4 | Z2: =IF(W2=0,"",Y2/W2) -> -0.063681592 | AA2: =Y2*H2 -> -320 | AB2: -320 | AC2: =ROUND(AA2-AB2,0) -> 0 | AD2: =0.5*W2 -> 50.25 | AE2: =-1*W2 -> -100.5 | AF2: =IF(D2="","OPEN",IF(ROUND(Z2,4)>=0.5,"TARGET",IF(ROUND(Z2,4)<=-1,"STOPLOSS",IF(G2<=15,"TIME","CHECK")))) -> TIME | AG2: =AF2 -> TIME | AI2: no | AJ2: =AB2 -> -320 | AK2: =MAX(0,AJ2) -> 0 | AL2: =AJ2-AK2 -> -320 | AM2: =IF(AB2>0,1,0) -> 0 | AN2: =IF(AB2<=0,1,0) -> 1
A3: 2 | B3: =IF(D3="","OPEN","CLOSED") -> CLOSED | C3: 44235.469 | D3: 44265.636 | E3: 44280 | F3: =INT(E3)-INT(C3) -> 45 | G3: =IF(D3="","",INT(E3)-INT(D3)) -> 15 | H3: 50 | I3: 15700 | J3: 15900 | K3: 14500 | L3: 14300 | M3: =J3-I3 -> 200 | N3: =K3-L3 -> 200 | O3: 206 | P3: 145.1 | Q3: 237 | R3: 195.1 | S3: 62 | T3: 29.7 | U3: 63.6 | V3: 42.1 | W3: =O3+Q3-P3-R3 -> 102.8 | X3: =S3+U3-T3-V3 -> 53.8 | Y3: =W3-X3 -> 49 | Z3: =IF(W3=0,"",Y3/W3) -> 0.4766537 | AA3: =Y3*H3 -> 2450 | AB3: 2450 | AC3: =ROUND(AA3-AB3,0) -> 0 | AD3: =0.5*W3 -> 51.4 | AE3: =-1*W3 -> -102.8 | AF3: =IF(D3="","OPEN",IF(ROUND(Z3,4)>=0.5,"TARGET",IF(ROUND(Z3,4)<=-1,"STOPLOSS",IF(G3<=15,"TIME","CHECK")))) -> TIME | AG3: =AF3 -> TIME | AI3: YES | AJ3: =AJ2+AB3 -> 2130 | AK3: =MAX(AK2,AJ3) -> 2130 | AL3: =AJ3-AK3 -> 0 | AM3: =IF(AB3>0,AM2+1,0) -> 1 | AN3: =IF(AB3<=0,AN2+1,0) -> 0
A4: 3 | B4: =IF(D4="","OPEN","CLOSED") -> CLOSED | C4: 44270.469 | D4: 44295.636 | E4: 44315 | F4: =INT(E4)-INT(C4) -> 45 | G4: =IF(D4="","",INT(E4)-INT(D4)) -> 20 | H4: 50 | I4: 15500 | J4: 15700 | K4: 14300 | L4: 14100 | M4: =J4-I4 -> 200 | N4: =K4-L4 -> 200 | O4: 184 | P4: 129 | Q4: 216.6 | R4: 168.2 | S4: 40.8 | T4: 17.7 | U4: 95.5 | V4: 67 | W4: =O4+Q4-P4-R4 -> 103.4 | X4: =S4+U4-T4-V4 -> 51.6 | Y4: =W4-X4 -> 51.8 | Z4: =IF(W4=0,"",Y4/W4) -> 0.50096712 | AA4: =Y4*H4 -> 2590 | AB4: 2589 | AC4: =ROUND(AA4-AB4,0) -> 1 | AD4: =0.5*W4 -> 51.7 | AE4: =-1*W4 -> -103.4 | AF4: =IF(D4="","OPEN",IF(ROUND(Z4,4)>=0.5,"TARGET",IF(ROUND(Z4,4)<=-1,"STOPLOSS",IF(G4<=15,"TIME","CHECK")))) -> TARGET | AG4: =AF4 -> TARGET | AI4: no | AJ4: =AJ3+AB4 -> 4719 | AK4: =MAX(AK3,AJ4) -> 4719 | AL4: =AJ4-AK4 -> 0 | AM4: =IF(AB4>0,AM3+1,0) -> 2 | AN4: =IF(AB4<=0,AN3+1,0) -> 0
A5: 4 | B5: =IF(D5="","OPEN","CLOSED") -> CLOSED | C5: 44298.469 | D5: 44328.636 | E5: 44343 | F5: =INT(E5)-INT(C5) -> 45 | G5: =IF(D5="","",INT(E5)-INT(D5)) -> 15 | H5: 50 | I5: 15100 | J5: 15300 | K5: 14000 | L5: 13800 | M5: =J5-I5 -> 200 | N5: =K5-L5 -> 200 | O5: 179.2 | P5: 123.3 | Q5: 236 | R5: 178.8 | S5: 72.5 | T5: 33.4 | U5: 45.6 | V5: 27.1 | W5: =O5+Q5-P5-R5 -> 113.1 | X5: =S5+U5-T5-V5 -> 57.6 | Y5: =W5-X5 -> 55.5 | Z5: =IF(W5=0,"",Y5/W5) -> 0.49071618 | AA5: =Y5*H5 -> 2775 | AB5: 2776 | AC5: =ROUND(AA5-AB5,0) -> -1 | AD5: =0.5*W5 -> 56.55 | AE5: =-1*W5 -> -113.1 | AF5: =IF(D5="","OPEN",IF(ROUND(Z5,4)>=0.5,"TARGET",IF(ROUND(Z5,4)<=-1,"STOPLOSS",IF(G5<=15,"TIME","CHECK")))) -> TIME | AG5: =AF5 -> TIME | AI5: no | AJ5: =AJ4+AB5 -> 7495 | AK5: =MAX(AK4,AJ5) -> 7495 | AL5: =AJ5-AK5 -> 0 | AM5: =IF(AB5>0,AM4+1,0) -> 3 | AN5: =IF(AB5<=0,AN4+1,0) -> 0
A6: 5 | B6: =IF(D6="","OPEN","CLOSED") -> CLOSED | C6: 44326.469 | D6: 44356.636 | E6: 44371 | F6: =INT(E6)-INT(C6) -> 45 | G6: =IF(D6="","",INT(E6)-INT(D6)) -> 15 | H6: 50 | I6: 15500 | J6: 15700 | K6: 14500 | L6: 14300 | M6: =J6-I6 -> 200 | N6: =K6-L6 -> 200 | O6: 175.1 | P6: 113.8 | Q6: 214.5 | R6: 165.8 | S6: 272.2 | T6: 152.2 | U6: 8.9 | V6: 5.7 | W6: =O6+Q6-P6-R6 -> 110 | X6: =S6+U6-T6-V6 -> 123.2 | Y6: =W6-X6 -> -13.2 | Z6: =IF(W6=0,"",Y6/W6) -> -0.12 | AA6: =Y6*H6 -> -660 | AB6: -660 | AC6: =ROUND(AA6-AB6,0) -> 0 | AD6: =0.5*W6 -> 55 | AE6: =-1*W6 -> -110 | AF6: =IF(D6="","OPEN",IF(ROUND(Z6,4)>=0.5,"TARGET",IF(ROUND(Z6,4)<=-1,"STOPLOSS",IF(G6<=15,"TIME","CHECK")))) -> TIME | AG6: =AF6 -> TIME | AI6: YES | AJ6: =AJ5+AB6 -> 6835 | AK6: =MAX(AK5,AJ6) -> 7495 | AL6: =AJ6-AK6 -> -660 | AM6: =IF(AB6>0,AM5+1,0) -> 0 | AN6: =IF(AB6<=0,AN5+1,0) -> 1
A7: 6 | B7: =IF(D7="","OPEN","CLOSED") -> CLOSED | C7: 44361.469 | D7: 44386.636 | E7: 44406 | F7: =INT(E7)-INT(C7) -> 45 | G7: =IF(D7="","",INT(E7)-INT(D7)) -> 20 | H7: 50 | I7: 16100 | J7: 16300 | K7: 15400 | L7: 15200 | M7: =J7-I7 -> 200 | N7: =K7-L7 -> 200 | O7: 144.8 | P7: 84.3 | Q7: 164.9 | R7: 114.2 | S7: 39.1 | T7: 15.6 | U7: 70.1 | V7: 38.7 | W7: =O7+Q7-P7-R7 -> 111.2 | X7: =S7+U7-T7-V7 -> 54.9 | Y7: =W7-X7 -> 56.3 | Z7: =IF(W7=0,"",Y7/W7) -> 0.50629496 | AA7: =Y7*H7 -> 2815 | AB7: 2815 | AC7: =ROUND(AA7-AB7,0) -> 0 | AD7: =0.5*W7 -> 55.6 | AE7: =-1*W7 -> -111.2 | AF7: =IF(D7="","OPEN",IF(ROUND(Z7,4)>=0.5,"TARGET",IF(ROUND(Z7,4)<=-1,"STOPLOSS",IF(G7<=15,"TIME","CHECK")))) -> TARGET | AG7: =AF7 -> TARGET | AI7: no | AJ7: =AJ6+AB7 -> 9650 | AK7: =MAX(AK6,AJ7) -> 9650 | AL7: =AJ7-AK7 -> 0 | AM7: =IF(AB7>0,AM6+1,0) -> 1 | AN7: =IF(AB7<=0,AN6+1,0) -> 0
A8: 7 | B8: =IF(D8="","OPEN","CLOSED") -> CLOSED | C8: 44389.469 | D8: 44419.636 | E8: 44434 | F8: =INT(E8)-INT(C8) -> 45 | G8: =IF(D8="","",INT(E8)-INT(D8)) -> 15 | H8: 50 | I8: 16100 | J8: 16300 | K8: 15500 | L8: 15300 | M8: =J8-I8 -> 200 | N8: =K8-L8 -> 200 | O8: 140.7 | P8: 74 | Q8: 153.1 | R8: 102.5 | S8: 262.3 | T8: 134.3 | U8: 12.8 | V8: 6.9 | W8: =O8+Q8-P8-R8 -> 117.3 | X8: =S8+U8-T8-V8 -> 133.9 | Y8: =W8-X8 -> -16.6 | Z8: =IF(W8=0,"",Y8/W8) -> -0.14151748 | AA8: =Y8*H8 -> -830 | AB8: -830 | AC8: =ROUND(AA8-AB8,0) -> 0 | AD8: =0.5*W8 -> 58.65 | AE8: =-1*W8 -> -117.3 | AF8: =IF(D8="","OPEN",IF(ROUND(Z8,4)>=0.5,"TARGET",IF(ROUND(Z8,4)<=-1,"STOPLOSS",IF(G8<=15,"TIME","CHECK")))) -> TIME | AG8: =AF8 -> TIME | AI8: no | AJ8: =AJ7+AB8 -> 8820 | AK8: =MAX(AK7,AJ8) -> 9650 | AL8: =AJ8-AK8 -> -830 | AM8: =IF(AB8>0,AM7+1,0) -> 0 | AN8: =IF(AB8<=0,AN7+1,0) -> 1
A9: 8 | B9: =IF(D9="","OPEN","CLOSED") -> CLOSED | C9: 44424.469 | D9: 44454.636 | E9: 44469 | F9: =INT(E9)-INT(C9) -> 45 | G9: =IF(D9="","",INT(E9)-INT(D9)) -> 15 | H9: 50 | I9: 16900 | J9: 17100 | K9: 16200 | L9: 16000 | M9: =J9-I9 -> 200 | N9: =K9-L9 -> 200 | O9: 122.7 | P9: 70 | Q9: 135.9 | R9: 95 | S9: 661.5 | T9: 475 | U9: 9.8 | V9: 8.9 | W9: =O9+Q9-P9-R9 -> 93.6 | X9: =S9+U9-T9-V9 -> 187.4 | Y9: =W9-X9 -> -93.8 | Z9: =IF(W9=0,"",Y9/W9) -> -1.0021368 | AA9: =Y9*H9 -> -4690 | AB9: -4689 | AC9: =ROUND(AA9-AB9,0) -> -1 | AD9: =0.5*W9 -> 46.8 | AE9: =-1*W9 -> -93.6 | AF9: =IF(D9="","OPEN",IF(ROUND(Z9,4)>=0.5,"TARGET",IF(ROUND(Z9,4)<=-1,"STOPLOSS",IF(G9<=15,"TIME","CHECK")))) -> STOPLOSS | AG9: =AF9 -> STOPLOSS | AI9: no | AJ9: =AJ8+AB9 -> 4131 | AK9: =MAX(AK8,AJ9) -> 9650 | AL9: =AJ9-AK9 -> -5519 | AM9: =IF(AB9>0,AM8+1,0) -> 0 | AN9: =IF(AB9<=0,AN8+1,0) -> 2
A10: 9 | B10: =IF(D10="","OPEN","CLOSED") -> CLOSED | C10: 44452.469 | D10: 44482.636 | E10: 44497 | F10: =INT(E10)-INT(C10) -> 45 | G10: =IF(D10="","",INT(E10)-INT(D10)) -> 15 | H10: 50 | I10: 17750 | J10: 17950 | K10: 16950 | L10: 16750 | M10: =J10-I10 -> 200 | N10: =K10-L10 -> 200 | O10: 136.9 | P10: 86 | Q10: 160.4 | R10: 117.1 | S10: 502.4 | T10: 342.4 | U10: 18.4 | V10: 15.8 | W10: =O10+Q10-P10-R10 -> 94.2 | X10: =S10+U10-T10-V10 -> 162.6 | Y10: =W10-X10 -> -68.4 | Z10: =IF(W10=0,"",Y10/W10) -> -0.72611465 | AA10: =Y10*H10 -> -3420 | AB10: -3421 | AC10: =ROUND(AA10-AB10,0) -> 1 | AD10: =0.5*W10 -> 47.1 | AE10: =-1*W10 -> -94.2 | AF10: =IF(D10="","OPEN",IF(ROUND(Z10,4)>=0.5,"TARGET",IF(ROUND(Z10,4)<=-1,"STOPLOSS",IF(G10<=15,"TIME","CHECK")))) -> TIME | AG10: =AF10 -> TIME | AI10: YES | AJ10: =AJ9+AB10 -> 710 | AK10: =MAX(AK9,AJ10) -> 9650 | AL10: =AJ10-AK10 -> -8940 | AM10: =IF(AB10>0,AM9+1,0) -> 0 | AN10: =IF(AB10<=0,AN9+1,0) -> 3
A11: 10 | B11: =IF(D11="","OPEN","CLOSED") -> CLOSED | C11: 44480.469 | D11: 44509.636 | E11: 44525 | F11: =INT(E11)-INT(C11) -> 45 | G11: =IF(D11="","",INT(E11)-INT(D11)) -> 16 | H11: 50 | I11: 18500 | J11: 18700 | K11: 17550 | L11: 17350 | M11: =J11-I11 -> 200 | N11: =K11-L11 -> 200 | O11: 189.9 | P11: 131 | Q11: 211.8 | R11: 153.6 | S11: 66.5 | T11: 33.6 | U11: 58.2 | V11: 34.2 | W11: =O11+Q11-P11-R11 -> 117.1 | X11: =S11+U11-T11-V11 -> 56.9 | Y11: =W11-X11 -> 60.2 | Z11: =IF(W11=0,"",Y11/W11) -> 0.51409052 | AA11: =Y11*H11 -> 3010 | AB11: 3010 | AC11: =ROUND(AA11-AB11,0) -> 0 | AD11: =0.5*W11 -> 58.55 | AE11: =-1*W11 -> -117.1 | AF11: =IF(D11="","OPEN",IF(ROUND(Z11,4)>=0.5,"TARGET",IF(ROUND(Z11,4)<=-1,"STOPLOSS",IF(G11<=15,"TIME","CHECK")))) -> TARGET | AG11: =AF11 -> TARGET | AI11: YES | AJ11: =AJ10+AB11 -> 3720 | AK11: =MAX(AK10,AJ11) -> 9650 | AL11: =AJ11-AK11 -> -5930 | AM11: =IF(AB11>0,AM10+1,0) -> 1 | AN11: =IF(AB11<=0,AN10+1,0) -> 0
A12: 11 | B12: =IF(D12="","OPEN","CLOSED") -> CLOSED | C12: 44515.469 | D12: 44545.636 | E12: 44560 | F12: =INT(E12)-INT(C12) -> 45 | G12: =IF(D12="","",INT(E12)-INT(D12)) -> 15 | H12: 50 | I12: 18700 | J12: 18900 | K12: 17750 | L12: 17550 | M12: =J12-I12 -> 200 | N12: =K12-L12 -> 200 | O12: 147.1 | P12: 94.7 | Q12: 167.3 | R12: 121.5 | S12: 4.8 | T12: 4.1 | U12: 550 | V12: 403.6 | W12: =O12+Q12-P12-R12 -> 98.2 | X12: =S12+U12-T12-V12 -> 147.1 | Y12: =W12-X12 -> -48.9 | Z12: =IF(W12=0,"",Y12/W12) -> -0.49796334 | AA12: =Y12*H12 -> -2445 | AB12: -2445 | AC12: =ROUND(AA12-AB12,0) -> 0 | AD12: =0.5*W12 -> 49.1 | AE12: =-1*W12 -> -98.2 | AF12: =IF(D12="","OPEN",IF(ROUND(Z12,4)>=0.5,"TARGET",IF(ROUND(Z12,4)<=-1,"STOPLOSS",IF(G12<=15,"TIME","CHECK")))) -> TIME | AG12: =AF12 -> TIME | AI12: no | AJ12: =AJ11+AB12 -> 1275 | AK12: =MAX(AK11,AJ12) -> 9650 | AL12: =AJ12-AK12 -> -8375 | AM12: =IF(AB12>0,AM11+1,0) -> 0 | AN12: =IF(AB12<=0,AN11+1,0) -> 1
A13: 12 | B13: =IF(D13="","OPEN","CLOSED") -> CLOSED | C13: 44543.469 | D13: 44573.636 | E13: 44588 | F13: =INT(E13)-INT(C13) -> 45 | G13: =IF(D13="","",INT(E13)-INT(D13)) -> 15 | H13: 50 | I13: 18100 | J13: 18300 | K13: 17200 | L13: 17000 | M13: =J13-I13 -> 200 | N13: =K13-L13 -> 200 | O13: 159.8 | P13: 103.3 | Q13: 185.5 | R13: 140.1 | S13: 297.1 | T13: 182 | U13: 20.9 | V13: 14.9 | W13: =O13+Q13-P13-R13 -> 101.9 | X13: =S13+U13-T13-V13 -> 121.1 | Y13: =W13-X13 -> -19.2 | Z13: =IF(W13=0,"",Y13/W13) -> -0.18842002 | AA13: =Y13*H13 -> -960 | AB13: -960 | AC13: =ROUND(AA13-AB13,0) -> 0 | AD13: =0.5*W13 -> 50.95 | AE13: =-1*W13 -> -101.9 | AF13: =IF(D13="","OPEN",IF(ROUND(Z13,4)>=0.5,"TARGET",IF(ROUND(Z13,4)<=-1,"STOPLOSS",IF(G13<=15,"TIME","CHECK")))) -> TIME | AG13: =AF13 -> TIME | AI13: YES | AJ13: =AJ12+AB13 -> 315 | AK13: =MAX(AK12,AJ13) -> 9650 | AL13: =AJ13-AK13 -> -9335 | AM13: =IF(AB13>0,AM12+1,0) -> 0 | AN13: =IF(AB13<=0,AN12+1,0) -> 2
A14: 13 | B14: =IF(D14="","OPEN","CLOSED") -> CLOSED | C14: 44571.469 | D14: 44601.636 | E14: 44616 | F14: =INT(E14)-INT(C14) -> 45 | G14: =IF(D14="","",INT(E14)-INT(D14)) -> 15 | H14: 50 | I14: 18650 | J14: 18850 | K14: 17450 | L14: 17250 | M14: =J14-I14 -> 200 | N14: =K14-L14 -> 200 | O14: 197.3 | P14: 144.2 | Q14: 236.4 | R14: 186.7 | S14: 8.1 | T14: 5.8 | U14: 214.6 | V14: 134.8 | W14: =O14+Q14-P14-R14 -> 102.8 | X14: =S14+U14-T14-V14 -> 82.1 | Y14: =W14-X14 -> 20.7 | Z14: =IF(W14=0,"",Y14/W14) -> 0.20136187 | AA14: =Y14*H14 -> 1035 | AB14: 1035 | AC14: =ROUND(AA14-AB14,0) -> 0 | AD14: =0.5*W14 -> 51.4 | AE14: =-1*W14 -> -102.8 | AF14: =IF(D14="","OPEN",IF(ROUND(Z14,4)>=0.5,"TARGET",IF(ROUND(Z14,4)<=-1,"STOPLOSS",IF(G14<=15,"TIME","CHECK")))) -> TIME | AG14: =AF14 -> TIME | AI14: YES | AJ14: =AJ13+AB14 -> 1350 | AK14: =MAX(AK13,AJ14) -> 9650 | AL14: =AJ14-AK14 -> -8300 | AM14: =IF(AB14>0,AM13+1,0) -> 1 | AN14: =IF(AB14<=0,AN13+1,0) -> 0
... A23: 22 | B23: =IF(D23="","OPEN","CLOSED") -> CLOSED | C23: 44844.469 | D23: 44874.636 | E23: 44889 | F23: =INT(E23)-INT(C23) -> 45 | G23: =IF(D23="","",INT(E23)-INT(D23)) -> 15 | H23: 50 | I23: 17800 | J23: 18000 | K23: 16500 | L23: 16300 | M23: =J23-I23 -> 200 | N23: =K23-L23 -> 200 | O23: 186 | P23: 133.6 | Q23: 217.9 | R23: 171 | S23: 495 | T23: 351.9 | U23: 4.1 | V23: 3.1 | W23: =O23+Q23-P23-R23 -> 99.3 | X23: =S23+U23-T23-V23 -> 144.1 | Y23: =W23-X23 -> -44.8 | Z23: =IF(W23=0,"",Y23/W23) -> -0.45115811 | AA23: =Y23*H23 -> -2240 | AB23: -2240 | AC23: =ROUND(AA23-AB23,0) -> 0 | AD23: =0.5*W23 -> 49.65 | AE23: =-1*W23 -> -99.3 | AF23: =IF(D23="","OPEN",IF(ROUND(Z23,4)>=0.5,"TARGET",IF(ROUND(Z23,4)<=-1,"STOPLOSS",IF(G23<=15,"TIME","CHECK")))) -> TIME | AG23: =AF23 -> TIME | AI23: YES | AJ23: =AJ22+AB23 -> -1470 | AK23: =MAX(AK22,AJ23) -> 9650 | AL23: =AJ23-AK23 -> -11120 | AM23: =IF(AB23>0,AM22+1,0) -> 0 | AN23: =IF(AB23<=0,AN22+1,0) -> 2
A24: 23 | B24: =IF(D24="","OPEN","CLOSED") -> CLOSED | C24: 44879.469 | D24: 44907.636 | E24: 44924 | F24: =INT(E24)-INT(C24) -> 45 | G24: =IF(D24="","",INT(E24)-INT(D24)) -> 17 | H24: 50 | I24: 18900 | J24: 19100 | K24: 18000 | L24: 17800 | M24: =J24-I24 -> 200 | N24: =K24-L24 -> 200 | O24: 157 | P24: 99.5 | Q24: 175.1 | R24: 127.4 | S24: 65.8 | T24: 26.4 | U24: 35.9 | V24: 20.8 | W24: =O24+Q24-P24-R24 -> 105.2 | X24: =S24+U24-T24-V24 -> 54.5 | Y24: =W24-X24 -> 50.7 | Z24: =IF(W24=0,"",Y24/W24) -> 0.48193916 | AA24: =Y24*H24 -> 2535 | AB24: 2535 | AC24: =ROUND(AA24-AB24,0) -> 0 | AD24: =0.5*W24 -> 52.6 | AE24: =-1*W24 -> -105.2 | AF24: =IF(D24="","OPEN",IF(ROUND(Z24,4)>=0.5,"TARGET",IF(ROUND(Z24,4)<=-1,"STOPLOSS",IF(G24<=15,"TIME","CHECK")))) -> CHECK | AG24: MANUAL | AH24: MANUAL exit in StockMock (user-confirmed). Note 14-Dec-22 (15 DTE) was a Wednesday trading day, so the rule-based engine will NOT exit here; expected reconciliation mismatch. | AI24: no | AJ24: =AJ23+AB24 -> 1065 | AK24: =MAX(AK23,AJ24) -> 9650 | AL24: =AJ24-AK24 -> -8585 | AM24: =IF(AB24>0,AM23+1,0) -> 1 | AN24: =IF(AB24<=0,AN23+1,0) -> 0
A25: 24 | B25: =IF(D25="","OPEN","CLOSED") -> CLOSED | C25: 44907.469 | D25: 44936.636 | E25: 44951 | F25: =INT(E25)-INT(C25) -> 44 | G25: =IF(D25="","",INT(E25)-INT(D25)) -> 15 | H25: 50 | I25: 19100 | J25: 19300 | K25: 18300 | L25: 18100 | M25: =J25-I25 -> 200 | N25: =K25-L25 -> 200 | O25: 149.9 | P25: 91 | Q25: 169.8 | R25: 121.5 | S25: 7.2 | T25: 5.8 | U25: 392 | V25: 260.7 | W25: =O25+Q25-P25-R25 -> 107.2 | X25: =S25+U25-T25-V25 -> 132.7 | Y25: =W25-X25 -> -25.5 | Z25: =IF(W25=0,"",Y25/W25) -> -0.23787313 | AA25: =Y25*H25 -> -1275 | AB25: -1277 | AC25: =ROUND(AA25-AB25,0) -> 2 | AD25: =0.5*W25 -> 53.6 | AE25: =-1*W25 -> -107.2 | AF25: =IF(D25="","OPEN",IF(ROUND(Z25,4)>=0.5,"TARGET",IF(ROUND(Z25,4)<=-1,"STOPLOSS",IF(G25<=15,"TIME","CHECK")))) -> TIME | AG25: =AF25 -> TIME | AI25: YES | AJ25: =AJ24+AB25 -> -212 | AK25: =MAX(AK24,AJ25) -> 9650 | AL25: =AJ25-AK25 -> -9862 | AM25: =IF(AB25>0,AM24+1,0) -> 0 | AN25: =IF(AB25<=0,AN24+1,0) -> 1
A26: 25 | B26: =IF(D26="","OPEN","CLOSED") -> CLOSED | C26: 44935.469 | D26: 44965.636 | E26: 44980 | F26: =INT(E26)-INT(C26) -> 45 | G26: =IF(D26="","",INT(E26)-INT(D26)) -> 15 | H26: 50 | I26: 18700 | J26: 18900 | K26: 17750 | L26: 17550 | M26: =J26-I26 -> 200 | N26: =K26-L26 -> 200 | O26: 169.9 | P26: 107 | Q26: 199.9 | R26: 151 | S26: 5.3 | T26: 3.8 | U26: 113.8 | V26: 65 | W26: =O26+Q26-P26-R26 -> 111.8 | X26: =S26+U26-T26-V26 -> 50.3 | Y26: =W26-X26 -> 61.5 | Z26: =IF(W26=0,"",Y26/W26) -> 0.55008945 | AA26: =Y26*H26 -> 3075 | AB26: 3075 | AC26: =ROUND(AA26-AB26,0) -> 0 | AD26: =0.5*W26 -> 55.9 | AE26: =-1*W26 -> -111.8 | AF26: =IF(D26="","OPEN",IF(ROUND(Z26,4)>=0.5,"TARGET",IF(ROUND(Z26,4)<=-1,"STOPLOSS",IF(G26<=15,"TIME","CHECK")))) -> TARGET | AG26: =AF26 -> TARGET | AI26: YES | AJ26: =AJ25+AB26 -> 2863 | AK26: =MAX(AK25,AJ26) -> 9650 | AL26: =AJ26-AK26 -> -6787 | AM26: =IF(AB26>0,AM25+1,0) -> 1 | AN26: =IF(AB26<=0,AN25+1,0) -> 0
A27: 26 | B27: =IF(D27="","OPEN","CLOSED") -> CLOSED | C27: 44970.469 | D27: 44991.636 | E27: 45014 | F27: =INT(E27)-INT(C27) -> 44 | G27: =IF(D27="","",INT(E27)-INT(D27)) -> 23 | H27: 50 | I27: 18300 | J27: 18500 | K27: 17500 | L27: 17300 | M27: =J27-I27 -> 200 | N27: =K27-L27 -> 200 | O27: 132.7 | P27: 77.5 | Q27: 157.9 | R27: 110 | S27: 24.1 | T27: 10.8 | U27: 93.3 | V27: 56.2 | W27: =O27+Q27-P27-R27 -> 103.1 | X27: =S27+U27-T27-V27 -> 50.4 | Y27: =W27-X27 -> 52.7 | Z27: =IF(W27=0,"",Y27/W27) -> 0.51115422 | AA27: =Y27*H27 -> 2635 | AB27: 2634 | AC27: =ROUND(AA27-AB27,0) -> 1 | AD27: =0.5*W27 -> 51.55 | AE27: =-1*W27 -> -103.1 | AF27: =IF(D27="","OPEN",IF(ROUND(Z27,4)>=0.5,"TARGET",IF(ROUND(Z27,4)<=-1,"STOPLOSS",IF(G27<=15,"TIME","CHECK")))) -> TARGET | AG27: =AF27 -> TARGET | AI27: no | AJ27: =AJ26+AB27 -> 5497 | AK27: =MAX(AK26,AJ27) -> 9650 | AL27: =AJ27-AK27 -> -4153 | AM27: =IF(AB27>0,AM26+1,0) -> 2 | AN27: =IF(AB27<=0,AN26+1,0) -> 0
A28: 27 | B28: =IF(D28="","OPEN","CLOSED") -> CLOSED | C28: 44998.469 | D28: 45028.636 | E28: 45043 | F28: =INT(E28)-INT(C28) -> 45 | G28: =IF(D28="","",INT(E28)-INT(D28)) -> 15 | H28: 50 | I28: 17900 | J28: 18100 | K28: 17100 | L28: 16900 | M28: =J28-I28 -> 200 | N28: =K28-L28 -> 200 | O28: 148.9 | P28: 91.5 | Q28: 162 | R28: 117.2 | S28: 123.8 | T28: 48 | U28: 17.3 | V28: 12.8 | W28: =O28+Q28-P28-R28 -> 102.2 | X28: =S28+U28-T28-V28 -> 80.3 | Y28: =W28-X28 -> 21.9 | Z28: =IF(W28=0,"",Y28/W28) -> 0.21428571 | AA28: =Y28*H28 -> 1095 | AB28: 1094 | AC28: =ROUND(AA28-AB28,0) -> 1 | AD28: =0.5*W28 -> 51.1 | AE28: =-1*W28 -> -102.2 | AF28: =IF(D28="","OPEN",IF(ROUND(Z28,4)>=0.5,"TARGET",IF(ROUND(Z28,4)<=-1,"STOPLOSS",IF(G28<=15,"TIME","CHECK")))) -> TIME | AG28: =AF28 -> TIME | AI28: no | AJ28: =AJ27+AB28 -> 6591 | AK28: =MAX(AK27,AJ28) -> 9650 | AL28: =AJ28-AK28 -> -3059 | AM28: =IF(AB28>0,AM27+1,0) -> 3 | AN28: =IF(AB28<=0,AN27+1,0) -> 0
A29: 28 | B29: =IF(D29="","OPEN","CLOSED") -> CLOSED | C29: 45026.469 | D29: 45056.636 | E29: 45071 | F29: =INT(E29)-INT(C29) -> 45 | G29: =IF(D29="","",INT(E29)-INT(D29)) -> 15 | H29: 50 | I29: 18100 | J29: 18300 | K29: 17300 | L29: 17100 | M29: =J29-I29 -> 200 | N29: =K29-L29 -> 200 | O29: 124.9 | P29: 70.85 | Q29: 139.8 | R29: 102.3 | S29: 316.9 | T29: 179.8 | U29: 10.7 | V29: 8.1 | W29: =O29+Q29-P29-R29 -> 91.55 | X29: =S29+U29-T29-V29 -> 139.7 | Y29: =W29-X29 -> -48.15 | Z29: =IF(W29=0,"",Y29/W29) -> -0.52594211 | AA29: =Y29*H29 -> -2407.5 | AB29: -2408 | AC29: =ROUND(AA29-AB29,0) -> 1 | AD29: =0.5*W29 -> 45.775 | AE29: =-1*W29 -> -91.55 | AF29: =IF(D29="","OPEN",IF(ROUND(Z29,4)>=0.5,"TARGET",IF(ROUND(Z29,4)<=-1,"STOPLOSS",IF(G29<=15,"TIME","CHECK")))) -> TIME | AG29: =AF29 -> TIME | AI29: YES | AJ29: =AJ28+AB29 -> 4183 | AK29: =MAX(AK28,AJ29) -> 9650 | AL29: =AJ29-AK29 -> -5467 | AM29: =IF(AB29>0,AM28+1,0) -> 0 | AN29: =IF(AB29<=0,AN28+1,0) -> 1
A30: 29 | B30: =IF(D30="","OPEN","CLOSED") -> CLOSED | C30: 45061.469 | D30: 45090.636 | E30: 45105 | F30: =INT(E30)-INT(C30) -> 44 | G30: =IF(D30="","",INT(E30)-INT(D30)) -> 15 | H30: 50 | I30: 18800 | J30: 19000 | K30: 18050 | L30: 17850 | M30: =J30-I30 -> 200 | N30: =K30-L30 -> 200 | O30: 144 | P30: 85.3 | Q30: 162.5 | R30: 114.8 | S30: 131.6 | T30: 51.2 | U30: 16.6 | V30: 11.15 | W30: =O30+Q30-P30-R30 -> 106.4 | X30: =S30+U30-T30-V30 -> 85.85 | Y30: =W30-X30 -> 20.55 | Z30: =IF(W30=0,"",Y30/W30) -> 0.1931391 | AA30: =Y30*H30 -> 1027.5 | AB30: 1028 | AC30: =ROUND(AA30-AB30,0) -> 0 | AD30: =0.5*W30 -> 53.2 | AE30: =-1*W30 -> -106.4 | AF30: =IF(D30="","OPEN",IF(ROUND(Z30,4)>=0.5,"TARGET",IF(ROUND(Z30,4)<=-1,"STOPLOSS",IF(G30<=15,"TIME","CHECK")))) -> TIME | AG30: =AF30 -> TIME | AI30: no | AJ30: =AJ29+AB30 -> 5211 | AK30: =MAX(AK29,AJ30) -> 9650 | AL30: =AJ30-AK30 -> -4439 | AM30: =IF(AB30>0,AM29+1,0) -> 1 | AN30: =IF(AB30<=0,AN29+1,0) -> 0
A31: 30 | B31: =IF(D31="","OPEN","CLOSED") -> CLOSED | C31: 45089.469 | D31: 45119.636 | E31: 45134 | F31: =INT(E31)-INT(C31) -> 45 | G31: =IF(D31="","",INT(E31)-INT(D31)) -> 15 | H31: 50 | I31: 19100 | J31: 19300 | K31: 18400 | L31: 18200 | M31: =J31-I31 -> 200 | N31: =K31-L31 -> 200 | O31: 120.7 | P31: 63.1 | Q31: 143 | R31: 96.4 | S31: 403.3 | T31: 246.9 | U31: 8.3 | V31: 5.8 | W31: =O31+Q31-P31-R31 -> 104.2 | X31: =S31+U31-T31-V31 -> 158.9 | Y31: =W31-X31 -> -54.7 | Z31: =IF(W31=0,"",Y31/W31) -> -0.52495202 | AA31: =Y31*H31 -> -2735 | AB31: -2736 | AC31: =ROUND(AA31-AB31,0) -> 1 | AD31: =0.5*W31 -> 52.1 | AE31: =-1*W31 -> -104.2 | AF31: =IF(D31="","OPEN",IF(ROUND(Z31,4)>=0.5,"TARGET",IF(ROUND(Z31,4)<=-1,"STOPLOSS",IF(G31<=15,"TIME","CHECK")))) -> TIME | AG31: =AF31 -> TIME | AI31: YES | AJ31: =AJ30+AB31 -> 2475 | AK31: =MAX(AK30,AJ31) -> 9650 | AL31: =AJ31-AK31 -> -7175 | AM31: =IF(AB31>0,AM30+1,0) -> 0 | AN31: =IF(AB31<=0,AN30+1,0) -> 1
A32: 31 | B32: =IF(D32="","OPEN","CLOSED") -> CLOSED | C32: 45124.469 | D32: 45147.636 | E32: 45169 | F32: =INT(E32)-INT(C32) -> 45 | G32: =IF(D32="","",INT(E32)-INT(D32)) -> 22 | H32: 50 | I32: 20100 | J32: 20300 | K32: 19350 | L32: 19150 | M32: =J32-I32 -> 200 | N32: =K32-L32 -> 200 | O32: 129.1 | P32: 72.3 | Q32: 147.7 | R32: 103 | S32: 37.5 | T32: 17.3 | U32: 66.7 | V32: 36.5 | W32: =O32+Q32-P32-R32 -> 101.5 | X32: =S32+U32-T32-V32 -> 50.4 | Y32: =W32-X32 -> 51.1 | Z32: =IF(W32=0,"",Y32/W32) -> 0.50344828 | AA32: =Y32*H32 -> 2555 | AB32: 2555 | AC32: =ROUND(AA32-AB32,0) -> 0 | AD32: =0.5*W32 -> 50.75 | AE32: =-1*W32 -> -101.5 | AF32: =IF(D32="","OPEN",IF(ROUND(Z32,4)>=0.5,"TARGET",IF(ROUND(Z32,4)<=-1,"STOPLOSS",IF(G32<=15,"TIME","CHECK")))) -> TARGET | AG32: =AF32 -> TARGET | AI32: no | AJ32: =AJ31+AB32 -> 5030 | AK32: =MAX(AK31,AJ32) -> 9650 | AL32: =AJ32-AK32 -> -4620 | AM32: =IF(AB32>0,AM31+1,0) -> 1 | AN32: =IF(AB32<=0,AN31+1,0) -> 0
A33: 32 | B33: =IF(D33="","OPEN","CLOSED") -> CLOSED | C33: 45152.469 | D33: 45182.636 | E33: 45197 | F33: =INT(E33)-INT(C33) -> 45 | G33: =IF(D33="","",INT(E33)-INT(D33)) -> 15 | H33: 50 | I33: 19800 | J33: 20000 | K33: 19100 | L33: 18900 | M33: =J33-I33 -> 200 | N33: =K33-L33 -> 200 | O33: 151.7 | P33: 94.5 | Q33: 164.6 | R33: 112.8 | S33: 388 | T33: 238.1 | U33: 20.3 | V33: 15.3 | W33: =O33+Q33-P33-R33 -> 109 | X33: =S33+U33-T33-V33 -> 154.9 | Y33: =W33-X33 -> -45.9 | Z33: =IF(W33=0,"",Y33/W33) -> -0.42110092 | AA33: =Y33*H33 -> -2295 | AB33: -2295 | AC33: =ROUND(AA33-AB33,0) -> 0 | AD33: =0.5*W33 -> 54.5 | AE33: =-1*W33 -> -109 | AF33: =IF(D33="","OPEN",IF(ROUND(Z33,4)>=0.5,"TARGET",IF(ROUND(Z33,4)<=-1,"STOPLOSS",IF(G33<=15,"TIME","CHECK")))) -> TIME | AG33: =AF33 -> TIME | AI33: no | AJ33: =AJ32+AB33 -> 2735 | AK33: =MAX(AK32,AJ33) -> 9650 | AL33: =AJ33-AK33 -> -6915 | AM33: =IF(AB33>0,AM32+1,0) -> 0 | AN33: =IF(AB33<=0,AN32+1,0) -> 1
A34: 33 | B34: =IF(D34="","OPEN","CLOSED") -> CLOSED | C34: 45180.469 | D34: 45210.636 | E34: 45225 | F34: =INT(E34)-INT(C34) -> 45 | G34: =IF(D34="","",INT(E34)-INT(D34)) -> 15 | H34: 50 | I34: 20300 | J34: 20500 | K34: 19700 | L34: 19500 | M34: =J34-I34 -> 200 | N34: =K34-L34 -> 200 | O34: 171 | P34: 99.5 | Q34: 144.8 | R34: 105.6 | S34: 21.6 | T34: 9.2 | U34: 105.6 | V34: 58.9 | W34: =O34+Q34-P34-R34 -> 110.7 | X34: =S34+U34-T34-V34 -> 59.1 | Y34: =W34-X34 -> 51.6 | Z34: =IF(W34=0,"",Y34/W34) -> 0.46612466 | AA34: =Y34*H34 -> 2580 | AB34: 2580 | AC34: =ROUND(AA34-AB34,0) -> 0 | AD34: =0.5*W34 -> 55.35 | AE34: =-1*W34 -> -110.7 | AF34: =IF(D34="","OPEN",IF(ROUND(Z34,4)>=0.5,"TARGET",IF(ROUND(Z34,4)<=-1,"STOPLOSS",IF(G34<=15,"TIME","CHECK")))) -> TIME | AG34: =AF34 -> TIME | AI34: YES | AJ34: =AJ33+AB34 -> 5315 | AK34: =MAX(AK33,AJ34) -> 9650 | AL34: =AJ34-AK34 -> -4335 | AM34: =IF(AB34>0,AM33+1,0) -> 1 | AN34: =IF(AB34<=0,AN33+1,0) -> 0
A35: 34 | B35: =IF(D35="","OPEN","CLOSED") -> CLOSED | C35: 45215.469 | D35: 45245.636 | E35: 45260 | F35: =INT(E35)-INT(C35) -> 45 | G35: =IF(D35="","",INT(E35)-INT(D35)) -> 15 | H35: 50 | I35: 20200 | J35: 20400 | K35: 19500 | L35: 19300 | M35: =J35-I35 -> 200 | N35: =K35-L35 -> 200 | O35: 136.3 | P35: 78.2 | Q35: 152.1 | R35: 107.2 | S35: 14.6 | T35: 5.3 | U35: 63.6 | V35: 31.9 | W35: =O35+Q35-P35-R35 -> 103 | X35: =S35+U35-T35-V35 -> 41 | Y35: =W35-X35 -> 62 | Z35: =IF(W35=0,"",Y35/W35) -> 0.60194175 | AA35: =Y35*H35 -> 3100 | AB35: 3100 | AC35: =ROUND(AA35-AB35,0) -> 0 | AD35: =0.5*W35 -> 51.5 | AE35: =-1*W35 -> -103 | AF35: =IF(D35="","OPEN",IF(ROUND(Z35,4)>=0.5,"TARGET",IF(ROUND(Z35,4)<=-1,"STOPLOSS",IF(G35<=15,"TIME","CHECK")))) -> TARGET | AG35: =AF35 -> TARGET | AI35: no | AJ35: =AJ34+AB35 -> 8415 | AK35: =MAX(AK34,AJ35) -> 9650 | AL35: =AJ35-AK35 -> -1235 | AM35: =IF(AB35>0,AM34+1,0) -> 2 | AN35: =IF(AB35<=0,AN34+1,0) -> 0
A36: 35 | B36: =IF(D36="","OPEN","CLOSED") -> CLOSED | C36: 45243.469 | D36: 45272.636 | E36: 45288 | F36: =INT(E36)-INT(C36) -> 45 | G36: =IF(D36="","",INT(E36)-INT(D36)) -> 16 | H36: 50 | I36: 19900 | J36: 20100 | K36: 19200 | L36: 19000 | M36: =J36-I36 -> 200 | N36: =K36-L36 -> 200 | O36: 136.9 | P36: 78.6 | Q36: 143.7 | R36: 103.2 | S36: 1144.5 | T36: 934.8 | U36: 6.7 | V36: 6.6 | W36: =O36+Q36-P36-R36 -> 98.8 | X36: =S36+U36-T36-V36 -> 209.8 | Y36: =W36-X36 -> -111 | Z36: =IF(W36=0,"",Y36/W36) -> -1.1234818 | AA36: =Y36*H36 -> -5550 | AB36: -5550 | AC36: =ROUND(AA36-AB36,0) -> 0 | AD36: =0.5*W36 -> 49.4 | AE36: =-1*W36 -> -98.8 | AF36: =IF(D36="","OPEN",IF(ROUND(Z36,4)>=0.5,"TARGET",IF(ROUND(Z36,4)<=-1,"STOPLOSS",IF(G36<=15,"TIME","CHECK")))) -> STOPLOSS | AG36: =AF36 -> STOPLOSS | AH36: SL hit at -112% of credit: daily-only check lets loss run past the 100% level. | AI36: YES | AJ36: =AJ35+AB36 -> 2865 | AK36: =MAX(AK35,AJ36) -> 9650 | AL36: =AJ36-AK36 -> -6785 | AM36: =IF(AB36>0,AM35+1,0) -> 0 | AN36: =IF(AB36<=0,AN35+1,0) -> 1
A37: 36 | B37: =IF(D37="","OPEN","CLOSED") -> CLOSED | C37: 45271.469 | D37: 45301.636 | E37: 45316 | F37: =INT(E37)-INT(C37) -> 45 | G37: =IF(D37="","",INT(E37)-INT(D37)) -> 15 | H37: 50 | I37: 21600 | J37: 21800 | K37: 20750 | L37: 20550 | M37: =J37-I37 -> 200 | N37: =K37-L37 -> 200 | O37: 172 | P37: 117.8 | Q37: 177.8 | R37: 130 | S37: 274.4 | T37: 166.8 | U37: 19.7 | V37: 13.2 | W37: =O37+Q37-P37-R37 -> 102 | X37: =S37+U37-T37-V37 -> 114.1 | Y37: =W37-X37 -> -12.1 | Z37: =IF(W37=0,"",Y37/W37) -> -0.11862745 | AA37: =Y37*H37 -> -605 | AB37: -605 | AC37: =ROUND(AA37-AB37,0) -> 0 | AD37: =0.5*W37 -> 51 | AE37: =-1*W37 -> -102 | AF37: =IF(D37="","OPEN",IF(ROUND(Z37,4)>=0.5,"TARGET",IF(ROUND(Z37,4)<=-1,"STOPLOSS",IF(G37<=15,"TIME","CHECK")))) -> TIME | AG37: =AF37 -> TIME | AI37: YES | AJ37: =AJ36+AB37 -> 2260 | AK37: =MAX(AK36,AJ37) -> 9650 | AL37: =AJ37-AK37 -> -7390 | AM37: =IF(AB37>0,AM36+1,0) -> 0 | AN37: =IF(AB37<=0,AN36+1,0) -> 2
A38: 37 | B38: =IF(D38="","OPEN","CLOSED") -> CLOSED | C38: 45306.469 | D38: 45336.636 | E38: 45351 | F38: =INT(E38)-INT(C38) -> 45 | G38: =IF(D38="","",INT(E38)-INT(D38)) -> 15 | H38: 50 | I38: 22750 | J38: 22950 | K38: 21600 | L38: 21400 | M38: =J38-I38 -> 200 | N38: =K38-L38 -> 200 | O38: 174.1 | P38: 121.5 | Q38: 188 | R38: 141.9 | S38: 22.1 | T38: 13.7 | U38: 137 | V38: 86.2 | W38: =O38+Q38-P38-R38 -> 98.7 | X38: =S38+U38-T38-V38 -> 59.2 | Y38: =W38-X38 -> 39.5 | Z38: =IF(W38=0,"",Y38/W38) -> 0.40020263 | AA38: =Y38*H38 -> 1975 | AB38: 1975 | AC38: =ROUND(AA38-AB38,0) -> 0 | AD38: =0.5*W38 -> 49.35 | AE38: =-1*W38 -> -98.7 | AF38: =IF(D38="","OPEN",IF(ROUND(Z38,4)>=0.5,"TARGET",IF(ROUND(Z38,4)<=-1,"STOPLOSS",IF(G38<=15,"TIME","CHECK")))) -> TIME | AG38: =AF38 -> TIME | AI38: no | AJ38: =AJ37+AB38 -> 4235 | AK38: =MAX(AK37,AJ38) -> 9650 | AL38: =AJ38-AK38 -> -5415 | AM38: =IF(AB38>0,AM37+1,0) -> 1 | AN38: =IF(AB38<=0,AN37+1,0) -> 0
A39: 38 | B39: =IF(D39="","OPEN","CLOSED") -> CLOSED | C39: 45334.469 | D39: 45364.636 | E39: 45379 | F39: =INT(E39)-INT(C39) -> 45 | G39: =IF(D39="","",INT(E39)-INT(D39)) -> 15 | H39: 50 | I39: 22500 | J39: 22700 | K39: 21350 | L39: 21150 | M39: =J39-I39 -> 200 | N39: =K39-L39 -> 200 | O39: 211 | P39: 154.7 | Q39: 234.1 | R39: 182.3 | S39: 91 | T39: 50.5 | U39: 49.7 | V39: 30.8 | W39: =O39+Q39-P39-R39 -> 108.1 | X39: =S39+U39-T39-V39 -> 59.4 | Y39: =W39-X39 -> 48.7 | Z39: =IF(W39=0,"",Y39/W39) -> 0.45050879 | AA39: =Y39*H39 -> 2435 | AB39: 2435 | AC39: =ROUND(AA39-AB39,0) -> 0 | AD39: =0.5*W39 -> 54.05 | AE39: =-1*W39 -> -108.1 | AF39: =IF(D39="","OPEN",IF(ROUND(Z39,4)>=0.5,"TARGET",IF(ROUND(Z39,4)<=-1,"STOPLOSS",IF(G39<=15,"TIME","CHECK")))) -> TIME | AG39: =AF39 -> TIME | AI39: YES | AJ39: =AJ38+AB39 -> 6670 | AK39: =MAX(AK38,AJ39) -> 9650 | AL39: =AJ39-AK39 -> -2980 | AM39: =IF(AB39>0,AM38+1,0) -> 2 | AN39: =IF(AB39<=0,AN38+1,0) -> 0
A40: 39 | B40: =IF(D40="","OPEN","CLOSED") -> CLOSED | C40: 45362.469 | D40: 45385.636 | E40: 45407 | F40: =INT(E40)-INT(C40) -> 45 | G40: =IF(D40="","",INT(E40)-INT(D40)) -> 22 | H40: 50 | I40: 23200 | J40: 23400 | K40: 22100 | L40: 21900 | M40: =J40-I40 -> 200 | N40: =K40-L40 -> 200 | O40: 206.6 | P40: 147.3 | Q40: 228.2 | R40: 175.3 | S40: 31.9 | T40: 14 | U40: 97.2 | V40: 59.7 | W40: =O40+Q40-P40-R40 -> 112.2 | X40: =S40+U40-T40-V40 -> 55.4 | Y40: =W40-X40 -> 56.8 | Z40: =IF(W40=0,"",Y40/W40) -> 0.50623886 | AA40: =Y40*H40 -> 2840 | AB40: 2840 | AC40: =ROUND(AA40-AB40,0) -> 0 | AD40: =0.5*W40 -> 56.1 | AE40: =-1*W40 -> -112.2 | AF40: =IF(D40="","OPEN",IF(ROUND(Z40,4)>=0.5,"TARGET",IF(ROUND(Z40,4)<=-1,"STOPLOSS",IF(G40<=15,"TIME","CHECK")))) -> TARGET | AG40: =AF40 -> TARGET | AI40: YES | AJ40: =AJ39+AB40 -> 9510 | AK40: =MAX(AK39,AJ40) -> 9650 | AL40: =AJ40-AK40 -> -140 | AM40: =IF(AB40>0,AM39+1,0) -> 3 | AN40: =IF(AB40<=0,AN39+1,0) -> 0
A41: 40 | B41: =IF(D41="","OPEN","CLOSED") -> CLOSED | C41: 45397.469 | D41: 45427.636 | E41: 45442 | F41: =INT(E41)-INT(C41) -> 45 | G41: =IF(D41="","",INT(E41)-INT(D41)) -> 15 | H41: 50 | I41: 23100 | J41: 23300 | K41: 22100 | L41: 21900 | M41: =J41-I41 -> 200 | N41: =K41-L41 -> 200 | O41: 160.8 | P41: 104.3 | Q41: 177.1 | R41: 131.6 | S41: 21.6 | T41: 11.9 | U41: 165 | V41: 105.7 | W41: =O41+Q41-P41-R41 -> 102 | X41: =S41+U41-T41-V41 -> 69 | Y41: =W41-X41 -> 33 | Z41: =IF(W41=0,"",Y41/W41) -> 0.32352941 | AA41: =Y41*H41 -> 1650 | AB41: 1649 | AC41: =ROUND(AA41-AB41,0) -> 1 | AD41: =0.5*W41 -> 51 | AE41: =-1*W41 -> -102 | AF41: =IF(D41="","OPEN",IF(ROUND(Z41,4)>=0.5,"TARGET",IF(ROUND(Z41,4)<=-1,"STOPLOSS",IF(G41<=15,"TIME","CHECK")))) -> TIME | AG41: =AF41 -> TIME | AI41: no | AJ41: =AJ40+AB41 -> 11159 | AK41: =MAX(AK40,AJ41) -> 11159 | AL41: =AJ41-AK41 -> 0 | AM41: =IF(AB41>0,AM40+1,0) -> 4 | AN41: =IF(AB41<=0,AN40+1,0) -> 0
A42: 41 | B42: =IF(D42="","OPEN","CLOSED") -> CLOSED | C42: 45425.469 | D42: 45455.636 | E42: 45470 | F42: =INT(E42)-INT(C42) -> 45 | G42: =IF(D42="","",INT(E42)-INT(D42)) -> 15 | H42: 50 | I42: 23000 | J42: 23200 | K42: 21300 | L42: 21100 | M42: =J42-I42 -> 200 | N42: =K42-L42 -> 200 | O42: 285.2 | P42: 225.5 | Q42: 346.9 | R42: 295.9 | S42: 472.4 | T42: 335.4 | U42: 7.3 | V42: 6.2 | W42: =O42+Q42-P42-R42 -> 110.7 | X42: =S42+U42-T42-V42 -> 138.1 | Y42: =W42-X42 -> -27.4 | Z42: =IF(W42=0,"",Y42/W42) -> -0.24751581 | AA42: =Y42*H42 -> -1370 | AB42: -1370 | AC42: =ROUND(AA42-AB42,0) -> 0 | AD42: =0.5*W42 -> 55.35 | AE42: =-1*W42 -> -110.7 | AF42: =IF(D42="","OPEN",IF(ROUND(Z42,4)>=0.5,"TARGET",IF(ROUND(Z42,4)<=-1,"STOPLOSS",IF(G42<=15,"TIME","CHECK")))) -> TIME | AG42: =AF42 -> TIME | AI42: YES | AJ42: =AJ41+AB42 -> 9789 | AK42: =MAX(AK41,AJ42) -> 11159 | AL42: =AJ42-AK42 -> -1370 | AM42: =IF(AB42>0,AM41+1,0) -> 0 | AN42: =IF(AB42<=0,AN41+1,0) -> 1
A43: 42 | B43: =IF(D43="","OPEN","CLOSED") -> CLOSED | C43: 45453.469 | D43: 45483.636 | E43: 45498 | F43: =INT(E43)-INT(C43) -> 45 | G43: =IF(D43="","",INT(E43)-INT(D43)) -> 15 | H43: 50 | I43: 24100 | J43: 24300 | K43: 22800 | L43: 22600 | M43: =J43-I43 -> 200 | N43: =K43-L43 -> 200 | O43: 222.1 | P43: 161.1 | Q43: 255.4 | R43: 207.3 | S43: 426 | T43: 308 | U43: 13.5 | V43: 10.7 | W43: =O43+Q43-P43-R43 -> 109.1 | X43: =S43+U43-T43-V43 -> 120.8 | Y43: =W43-X43 -> -11.7 | Z43: =IF(W43=0,"",Y43/W43) -> -0.10724106 | AA43: =Y43*H43 -> -585 | AB43: -585 | AC43: =ROUND(AA43-AB43,0) -> 0 | AD43: =0.5*W43 -> 54.55 | AE43: =-1*W43 -> -109.1 | AF43: =IF(D43="","OPEN",IF(ROUND(Z43,4)>=0.5,"TARGET",IF(ROUND(Z43,4)<=-1,"STOPLOSS",IF(G43<=15,"TIME","CHECK")))) -> TIME | AG43: =AF43 -> TIME | AI43: YES | AJ43: =AJ42+AB43 -> 9204 | AK43: =MAX(AK42,AJ43) -> 11159 | AL43: =AJ43-AK43 -> -1955 | AM43: =IF(AB43>0,AM42+1,0) -> 0 | AN43: =IF(AB43<=0,AN42+1,0) -> 2
A44: 43 | B44: =IF(D44="","OPEN","CLOSED") -> CLOSED | C44: 45488.469 | D44: 45518.636 | E44: 45533 | F44: =INT(E44)-INT(C44) -> 45 | G44: =IF(D44="","",INT(E44)-INT(D44)) -> 15 | H44: 50 | I44: 25300 | J44: 25500 | K44: 24100 | L44: 23900 | M44: =J44-I44 -> 200 | N44: =K44-L44 -> 200 | O44: 207.5 | P44: 150 | Q44: 231 | R44: 183 | S44: 8.8 | T44: 6.3 | U44: 229.7 | V44: 162 | W44: =O44+Q44-P44-R44 -> 105.5 | X44: =S44+U44-T44-V44 -> 70.2 | Y44: =W44-X44 -> 35.3 | Z44: =IF(W44=0,"",Y44/W44) -> 0.33459716 | AA44: =Y44*H44 -> 1765 | AB44: 1766 | AC44: =ROUND(AA44-AB44,0) -> -1 | AD44: =0.5*W44 -> 52.75 | AE44: =-1*W44 -> -105.5 | AF44: =IF(D44="","OPEN",IF(ROUND(Z44,4)>=0.5,"TARGET",IF(ROUND(Z44,4)<=-1,"STOPLOSS",IF(G44<=15,"TIME","CHECK")))) -> TIME | AG44: =AF44 -> TIME | AI44: no | AJ44: =AJ43+AB44 -> 10970 | AK44: =MAX(AK43,AJ44) -> 11159 | AL44: =AJ44-AK44 -> -189 | AM44: =IF(AB44>0,AM43+1,0) -> 1 | AN44: =IF(AB44<=0,AN43+1,0) -> 0
A45: 44 | B45: =IF(D45="","OPEN","CLOSED") -> CLOSED | C45: 45516.469 | D45: 45546.636 | E45: 45561 | F45: =INT(E45)-INT(C45) -> 45 | G45: =IF(D45="","",INT(E45)-INT(D45)) -> 15 | H45: 50 | I45: 25200 | J45: 25400 | K45: 24000 | L45: 23800 | M45: =J45-I45 -> 200 | N45: =K45-L45 -> 200 | O45: 223.5 | P45: 162.9 | Q45: 260 | R45: 211.9 | S45: 135.2 | T45: 74.8 | U45: 43.8 | V45: 30.2 | W45: =O45+Q45-P45-R45 -> 108.7 | X45: =S45+U45-T45-V45 -> 74 | Y45: =W45-X45 -> 34.7 | Z45: =IF(W45=0,"",Y45/W45) -> 0.31922723 | AA45: =Y45*H45 -> 1735 | AB45: 1735 | AC45: =ROUND(AA45-AB45,0) -> 0 | AD45: =0.5*W45 -> 54.35 | AE45: =-1*W45 -> -108.7 | AF45: =IF(D45="","OPEN",IF(ROUND(Z45,4)>=0.5,"TARGET",IF(ROUND(Z45,4)<=-1,"STOPLOSS",IF(G45<=15,"TIME","CHECK")))) -> TIME | AG45: =AF45 -> TIME | AI45: YES | AJ45: =AJ44+AB45 -> 12705 | AK45: =MAX(AK44,AJ45) -> 12705 | AL45: =AJ45-AK45 -> 0 | AM45: =IF(AB45>0,AM44+1,0) -> 2 | AN45: =IF(AB45<=0,AN44+1,0) -> 0
A46: 45 | B46: =IF(D46="","OPEN","CLOSED") -> CLOSED | C46: 45551.469 | D46: 45581.636 | E46: 45596 | F46: =INT(E46)-INT(C46) -> 45 | G46: =IF(D46="","",INT(E46)-INT(D46)) -> 15 | H46: 50 | I46: 26050 | J46: 26250 | K46: 25000 | L46: 24800 | M46: =J46-I46 -> 200 | N46: =K46-L46 -> 200 | O46: 187.4 | P46: 137.1 | Q46: 226.2 | R46: 179.3 | S46: 13.8 | T46: 9.6 | U46: 207 | V46: 135.1 | W46: =O46+Q46-P46-R46 -> 97.2 | X46: =S46+U46-T46-V46 -> 76.1 | Y46: =W46-X46 -> 21.1 | Z46: =IF(W46=0,"",Y46/W46) -> 0.21707819 | AA46: =Y46*H46 -> 1055 | AB46: 1055 | AC46: =ROUND(AA46-AB46,0) -> 0 | AD46: =0.5*W46 -> 48.6 | AE46: =-1*W46 -> -97.2 | AF46: =IF(D46="","OPEN",IF(ROUND(Z46,4)>=0.5,"TARGET",IF(ROUND(Z46,4)<=-1,"STOPLOSS",IF(G46<=15,"TIME","CHECK")))) -> TIME | AG46: =AF46 -> TIME | AI46: no | AJ46: =AJ45+AB46 -> 13760 | AK46: =MAX(AK45,AJ46) -> 13760 | AL46: =AJ46-AK46 -> 0 | AM46: =IF(AB46>0,AM45+1,0) -> 3 | AN46: =IF(AB46<=0,AN45+1,0) -> 0
A47: 46 | B47: =IF(D47="","OPEN","CLOSED") -> CLOSED | C47: 45579.469 | D47: 45609.636 | E47: 45624 | F47: =INT(E47)-INT(C47) -> 45 | G47: =IF(D47="","",INT(E47)-INT(D47)) -> 15 | H47: 50 | I47: 26000 | J47: 26200 | K47: 24700 | L47: 24500 | M47: =J47-I47 -> 200 | N47: =K47-L47 -> 200 | O47: 192.2 | P47: 132.4 | Q47: 230.2 | R47: 185.1 | S47: 6.5 | T47: 6 | U47: 1068 | V47: 858.7 | W47: =O47+Q47-P47-R47 -> 104.9 | X47: =S47+U47-T47-V47 -> 209.8 | Y47: =W47-X47 -> -104.9 | Z47: =IF(W47=0,"",Y47/W47) -> -1 | AA47: =Y47*H47 -> -5245 | AB47: -5245 | AC47: =ROUND(AA47-AB47,0) -> 0 | AD47: =0.5*W47 -> 52.45 | AE47: =-1*W47 -> -104.9 | AF47: =IF(D47="","OPEN",IF(ROUND(Z47,4)>=0.5,"TARGET",IF(ROUND(Z47,4)<=-1,"STOPLOSS",IF(G47<=15,"TIME","CHECK")))) -> STOPLOSS | AG47: =AF47 -> STOPLOSS | AI47: YES | AJ47: =AJ46+AB47 -> 8515 | AK47: =MAX(AK46,AJ47) -> 13760 | AL47: =AJ47-AK47 -> -5245 | AM47: =IF(AB47>0,AM46+1,0) -> 0 | AN47: =IF(AB47<=0,AN46+1,0) -> 1
A48: 47 | B48: =IF(D48="","OPEN","CLOSED") -> CLOSED | C48: 45607.469 | D48: 45637.636 | E48: 45652 | F48: =INT(E48)-INT(C48) -> 45 | G48: =IF(D48="","",INT(E48)-INT(D48)) -> 15 | H48: 50 | I48: 25100 | J48: 25300 | K48: 23900 | L48: 23700 | M48: =J48-I48 -> 200 | N48: =K48-L48 -> 200 | O48: 195.7 | P48: 137.5 | Q48: 214.2 | R48: 170 | S48: 100.6 | T48: 53.2 | U48: 44 | V48: 28.5 | W48: =O48+Q48-P48-R48 -> 102.4 | X48: =S48+U48-T48-V48 -> 62.9 | Y48: =W48-X48 -> 39.5 | Z48: =IF(W48=0,"",Y48/W48) -> 0.38574219 | AA48: =Y48*H48 -> 1975 | AB48: 1975 | AC48: =ROUND(AA48-AB48,0) -> 0 | AD48: =0.5*W48 -> 51.2 | AE48: =-1*W48 -> -102.4 | AF48: =IF(D48="","OPEN",IF(ROUND(Z48,4)>=0.5,"TARGET",IF(ROUND(Z48,4)<=-1,"STOPLOSS",IF(G48<=15,"TIME","CHECK")))) -> TIME | AG48: =AF48 -> TIME | AI48: YES | AJ48: =AJ47+AB48 -> 10490 | AK48: =MAX(AK47,AJ48) -> 13760 | AL48: =AJ48-AK48 -> -3270 | AM48: =IF(AB48>0,AM47+1,0) -> 1 | AN48: =IF(AB48<=0,AN47+1,0) -> 0
...

Sheet Legs
A1: Trade # | B1: Src Row | C1: Side | D1: Type | E1: Strike | F1: Expiry | G1: Entry DT | H1: Exit DT | I1: Entry Px | J1: Exit Px | K1: Diff (rep) | L1: Profit (rep) | M1: Delta (rep) | N1: Qty (derived) | O1: Diff check | P1: Profit check
A2: 1 | B2: 21 | C2: Buy | D2: PE | E2: 13600 | F2: 44252 | G2: 44207.469 | H2: 44237.636 | I2: 168.7 | J2: 16.6 | K2: -152.1 | L2: -7605 | M2: -0.04 | N2: 50 | O2: =IF(ABS((J2-I2)-K2)<=0.051,"OK","MISMATCH") -> OK | P2: =IF(ABS(IF(C2="Buy",1,-1)*(J2-I2)*N2-L2)<=1.01,"OK","MISMATCH") -> OK
A3: 1 | B3: 22 | C3: Sell | D3: CE | E3: 15100 | F3: 44252 | G3: 44207.469 | H3: 44237.636 | I3: 199.1 | J3: 256.2 | K3: 57.1 | L3: -2855 | M3: -0.53 | N3: 50 | O3: =IF(ABS((J3-I3)-K3)<=0.051,"OK","MISMATCH") -> OK | P3: =IF(ABS(IF(C3="Buy",1,-1)*(J3-I3)*N3-L3)<=1.01,"OK","MISMATCH") -> OK
A4: 1 | B4: 23 | C4: Buy | D4: CE | E4: 15300 | F4: 44252 | G4: 44207.469 | H4: 44237.636 | I4: 147.3 | J4: 155.3 | K4: 8 | L4: 400 | M4: 0.39 | N4: 50 | O4: =IF(ABS((J4-I4)-K4)<=0.051,"OK","MISMATCH") -> OK | P4: =IF(ABS(IF(C4="Buy",1,-1)*(J4-I4)*N4-L4)<=1.01,"OK","MISMATCH") -> OK
A5: 1 | B5: 24 | C5: Sell | D5: PE | E5: 13800 | F5: 44252 | G5: 44207.469 | H5: 44237.636 | I5: 217.4 | J5: 22.6 | K5: -194.8 | L5: 9740 | M5: 0.06 | N5: 50 | O5: =IF(ABS((J5-I5)-K5)<=0.051,"OK","MISMATCH") -> OK | P5: =IF(ABS(IF(C5="Buy",1,-1)*(J5-I5)*N5-L5)<=1.01,"OK","MISMATCH") -> OK
A6: 2 | B6: 29 | C6: Sell | D6: PE | E6: 14500 | F6: 44280 | G6: 44235.469 | H6: 44265.636 | I6: 237 | J6: 63.6 | K6: -173.4 | L6: 8670 | M6: 0.16 | N6: 50 | O6: =IF(ABS((J6-I6)-K6)<=0.051,"OK","MISMATCH") -> OK | P6: =IF(ABS(IF(C6="Buy",1,-1)*(J6-I6)*N6-L6)<=1.01,"OK","MISMATCH") -> OK
A7: 2 | B7: 30 | C7: Buy | D7: PE | E7: 14300 | F7: 44280 | G7: 44235.469 | H7: 44265.636 | I7: 195.1 | J7: 42.1 | K7: -153 | L7: -7650 | M7: -0.11 | N7: 50 | O7: =IF(ABS((J7-I7)-K7)<=0.051,"OK","MISMATCH") -> OK | P7: =IF(ABS(IF(C7="Buy",1,-1)*(J7-I7)*N7-L7)<=1.01,"OK","MISMATCH") -> OK
A8: 2 | B8: 31 | C8: Sell | D8: CE | E8: 15700 | F8: 44280 | G8: 44235.469 | H8: 44265.636 | I8: 206 | J8: 62 | K8: -144 | L8: 7200 | M8: -0.2 | N8: 50 | O8: =IF(ABS((J8-I8)-K8)<=0.051,"OK","MISMATCH") -> OK | P8: =IF(ABS(IF(C8="Buy",1,-1)*(J8-I8)*N8-L8)<=1.01,"OK","MISMATCH") -> OK
A9: 2 | B9: 32 | C9: Buy | D9: CE | E9: 15900 | F9: 44280 | G9: 44235.469 | H9: 44265.636 | I9: 145.1 | J9: 29.7 | K9: -115.4 | L9: -5770 | M9: 0.11 | N9: 50 | O9: =IF(ABS((J9-I9)-K9)<=0.051,"OK","MISMATCH") -> OK | P9: =IF(ABS(IF(C9="Buy",1,-1)*(J9-I9)*N9-L9)<=1.01,"OK","MISMATCH") -> OK
A10: 3 | B10: 37 | C10: Sell | D10: PE | E10: 14300 | F10: 44315 | G10: 44270.469 | H10: 44295.636 | I10: 216.6 | J10: 95.5 | K10: -121.1 | L10: 6055 | M10: 0.21 | N10: 50 | O10: =IF(ABS((J10-I10)-K10)<=0.051,"OK","MISMATCH") -> OK | P10: =IF(ABS(IF(C10="Buy",1,-1)*(J10-I10)*N10-L10)<=1.01,"OK","MISMATCH") -> OK
A11: 3 | B11: 38 | C11: Buy | D11: PE | E11: 14100 | F11: 44315 | G11: 44270.469 | H11: 44295.636 | I11: 168.2 | J11: 67 | K11: -101.2 | L11: -5060 | M11: -0.15 | N11: 50 | O11: =IF(ABS((J11-I11)-K11)<=0.051,"OK","MISMATCH") -> OK | P11: =IF(ABS(IF(C11="Buy",1,-1)*(J11-I11)*N11-L11)<=1.01,"OK","MISMATCH") -> OK
A12: 3 | B12: 39 | C12: Sell | D12: CE | E12: 15500 | F12: 44315 | G12: 44270.469 | H12: 44295.636 | I12: 184 | J12: 40.8 | K12: -143.2 | L12: 7159 | M12: -0.14 | N12: 50 | O12: =IF(ABS((J12-I12)-K12)<=0.051,"OK","MISMATCH") -> OK | P12: =IF(ABS(IF(C12="Buy",1,-1)*(J12-I12)*N12-L12)<=1.01,"OK","MISMATCH") -> OK
A13: 3 | B13: 40 | C13: Buy | D13: CE | E13: 15700 | F13: 44315 | G13: 44270.469 | H13: 44295.636 | I13: 129 | J13: 17.7 | K13: -111.3 | L13: -5565 | M13: 0.07 | N13: 50 | O13: =IF(ABS((J13-I13)-K13)<=0.051,"OK","MISMATCH") -> OK | P13: =IF(ABS(IF(C13="Buy",1,-1)*(J13-I13)*N13-L13)<=1.01,"OK","MISMATCH") -> OK
... A265: 66 | B265: 544 | C265: Sell | D265: PE | E265: 23700 | F265: 46259 | G265: 46216.469 | H265: 46244.636 | I265: 214.9 | J265: 22.7 | K265: -192.2 | L265: 12493 | M265: 0.07 | N265: 65 | O265: =IF(ABS((J265-I265)-K265)<=0.051,"OK","MISMATCH") -> OK | P265: =IF(ABS(IF(C265="Buy",1,-1)*(J265-I265)*N265-L265)<=1.01,"OK","MISMATCH") -> OK
A266: 67 | B266: 549 | C266: Sell | D266: PE | E266: 24000 | F266: 46294 | G266: 46251.469 | I266: 188.1 | J266: 565.2 | K266: 377.1 | L266: -24511 | M266: 0.81 | N266: 65 | O266: =IF(ABS((J266-I266)-K266)<=0.051,"OK","MISMATCH") -> OK | P266: =IF(ABS(IF(C266="Buy",1,-1)*(J266-I266)*N266-L266)<=1.01,"OK","MISMATCH") -> OK
A267: 67 | B267: 550 | C267: Buy | D267: PE | E267: 23800 | F267: 46294 | G267: 46251.469 | I267: 138.9 | J267: 410.1 | K267: 271.2 | L267: 17628 | M267: -0.71 | N267: 65 | O267: =IF(ABS((J267-I267)-K267)<=0.051,"OK","MISMATCH") -> OK | P267: =IF(ABS(IF(C267="Buy",1,-1)*(J267-I267)*N267-L267)<=1.01,"OK","MISMATCH") -> OK
A268: 67 | B268: 551 | C268: Sell | D268: CE | E268: 24900 | F268: 46294 | G268: 46251.469 | I268: 156.8 | J268: 8.6 | K268: -148.2 | L268: 9633 | M268: -0.03 | N268: 65 | O268: =IF(ABS((J268-I268)-K268)<=0.051,"OK","MISMATCH") -> OK | P268: =IF(ABS(IF(C268="Buy",1,-1)*(J268-I268)*N268-L268)<=1.01,"OK","MISMATCH") -> OK
A269: 67 | B269: 552 | C269: Buy | D269: CE | E269: 25100 | F269: 46294 | G269: 46251.469 | I269: 103.3 | J269: 7 | K269: -96.3 | L269: -6259 | M269: 0.02 | N269: 65 | O269: =IF(ABS((J269-I269)-K269)<=0.051,"OK","MISMATCH") -> OK | P269: =IF(ABS(IF(C269="Buy",1,-1)*(J269-I269)*N269-L269)<=1.01,"OK","MISMATCH") -> OK

Sheet Automation Input
A1: trade_id | B1: entry_date | C1: entry_time | D1: expiry | E1: sell_ce | F1: buy_ce | G1: sell_pe | H1: buy_pe | I1: qty_stockmock | J1: ref_exit_date | K1: ref_exit_reason | L1: ref_pnl_pts | M1: ref_pnl_rs | N1: ref_note
A2: 1 | B2: 44207 | C2: 11:16 | D2: 44252 | E2: 15100 | F2: 15300 | G2: 13800 | H2: 13600 | I2: 50 | J2: 44237 | K2: TIME | L2: -6.4 | M2: -320
A3: 2 | B3: 44235 | C3: 11:16 | D3: 44280 | E3: 15700 | F3: 15900 | G3: 14500 | H3: 14300 | I3: 50 | J3: 44265 | K3: TIME | L3: 49 | M3: 2450
A4: 3 | B4: 44270 | C4: 11:16 | D4: 44315 | E4: 15500 | F4: 15700 | G4: 14300 | H4: 14100 | I4: 50 | J4: 44295 | K4: TARGET | L4: 51.8 | M4: 2589
A5: 4 | B5: 44298 | C5: 11:16 | D5: 44343 | E5: 15100 | F5: 15300 | G5: 14000 | H5: 13800 | I5: 50 | J5: 44328 | K5: TIME | L5: 55.5 | M5: 2776
A6: 5 | B6: 44326 | C6: 11:16 | D6: 44371 | E6: 15500 | F6: 15700 | G6: 14500 | H6: 14300 | I6: 50 | J6: 44356 | K6: TIME | L6: -13.2 | M6: -660
A7: 6 | B7: 44361 | C7: 11:16 | D7: 44406 | E7: 16100 | F7: 16300 | G7: 15400 | H7: 15200 | I7: 50 | J7: 44386 | K7: TARGET | L7: 56.3 | M7: 2815
A8: 7 | B8: 44389 | C8: 11:16 | D8: 44434 | E8: 16100 | F8: 16300 | G8: 15500 | H8: 15300 | I8: 50 | J8: 44419 | K8: TIME | L8: -16.6 | M8: -830
A9: 8 | B9: 44424 | C9: 11:16 | D9: 44469 | E9: 16900 | F9: 17100 | G9: 16200 | H9: 16000 | I9: 50 | J9: 44454 | K9: STOPLOSS | L9: -93.8 | M9: -4689
A10: 9 | B10: 44452 | C10: 11:16 | D10: 44497 | E10: 17750 | F10: 17950 | G10: 16950 | H10: 16750 | I10: 50 | J10: 44482 | K10: TIME | L10: -68.4 | M10: -3421
A11: 10 | B11: 44480 | C11: 11:16 | D11: 44525 | E11: 18500 | F11: 18700 | G11: 17550 | H11: 17350 | I11: 50 | J11: 44509 | K11: TARGET | L11: 60.2 | M11: 3010
A12: 11 | B12: 44515 | C12: 11:16 | D12: 44560 | E12: 18700 | F12: 18900 | G12: 17750 | H12: 17550 | I12: 50 | J12: 44545 | K12: TIME | L12: -48.9 | M12: -2445
A13: 12 | B13: 44543 | C13: 11:16 | D13: 44588 | E13: 18100 | F13: 18300 | G13: 17200 | H13: 17000 | I13: 50 | J13: 44573 | K13: TIME | L13: -19.2 | M13: -960
... A23: 22 | B23: 44844 | C23: 11:16 | D23: 44889 | E23: 17800 | F23: 18000 | G23: 16500 | H23: 16300 | I23: 50 | J23: 44874 | K23: TIME | L23: -44.8 | M23: -2240
A24: 23 | B24: 44879 | C24: 11:16 | D24: 44924 | E24: 18900 | F24: 19100 | G24: 18000 | H24: 17800 | I24: 50 | J24: 44907 | K24: MANUAL | L24: 50.7 | M24: 2535 | N24: manual exit - expected mismatch
A25: 24 | B25: 44907 | C25: 11:16 | D25: 44951 | E25: 19100 | F25: 19300 | G25: 18300 | H25: 18100 | I25: 50 | J25: 44936 | K25: TIME | L25: -25.5 | M25: -1277
A26: 25 | B26: 44935 | C26: 11:16 | D26: 44980 | E26: 18700 | F26: 18900 | G26: 17750 | H26: 17550 | I26: 50 | J26: 44965 | K26: TARGET | L26: 61.5 | M26: 3075
A27: 26 | B27: 44970 | C27: 11:16 | D27: 45014 | E27: 18300 | F27: 18500 | G27: 17500 | H27: 17300 | I27: 50 | J27: 44991 | K27: TARGET | L27: 52.7 | M27: 2634
A28: 27 | B28: 44998 | C28: 11:16 | D28: 45043 | E28: 17900 | F28: 18100 | G28: 17100 | H28: 16900 | I28: 50 | J28: 45028 | K28: TIME | L28: 21.9 | M28: 1094
A29: 28 | B29: 45026 | C29: 11:16 | D29: 45071 | E29: 18100 | F29: 18300 | G29: 17300 | H29: 17100 | I29: 50 | J29: 45056 | K29: TIME | L29: -48.15 | M29: -2408
A30: 29 | B30: 45061 | C30: 11:16 | D30: 45105 | E30: 18800 | F30: 19000 | G30: 18050 | H30: 17850 | I30: 50 | J30: 45090 | K30: TIME | L30: 20.55 | M30: 1028
A31: 30 | B31: 45089 | C31: 11:16 | D31: 45134 | E31: 19100 | F31: 19300 | G31: 18400 | H31: 18200 | I31: 50 | J31: 45119 | K31: TIME | L31: -54.7 | M31: -2736
A32: 31 | B32: 45124 | C32: 11:16 | D32: 45169 | E32: 20100 | F32: 20300 | G32: 19350 | H32: 19150 | I32: 50 | J32: 45147 | K32: TARGET | L32: 51.1 | M32: 2555
A33: 32 | B33: 45152 | C33: 11:16 | D33: 45197 | E33: 19800 | F33: 20000 | G33: 19100 | H33: 18900 | I33: 50 | J33: 45182 | K33: TIME | L33: -45.9 | M33: -2295
A34: 33 | B34: 45180 | C34: 11:16 | D34: 45225 | E34: 20300 | F34: 20500 | G34: 19700 | H34: 19500 | I34: 50 | J34: 45210 | K34: TIME | L34: 51.6 | M34: 2580
A35: 34 | B35: 45215 | C35: 11:16 | D35: 45260 | E35: 20200 | F35: 20400 | G35: 19500 | H35: 19300 | I35: 50 | J35: 45245 | K35: TARGET | L35: 62 | M35: 3100
A36: 35 | B36: 45243 | C36: 11:16 | D36: 45288 | E36: 19900 | F36: 20100 | G36: 19200 | H36: 19000 | I36: 50 | J36: 45272 | K36: STOPLOSS | L36: -111 | M36: -5550
... A62: 61 | B62: 46034 | C62: 11:16 | D62: 46077 | E62: 26300 | F62: 26500 | G62: 25200 | H62: 25000 | I62: 65 | J62: 46062 | K62: TARGET | L62: 50.8 | M62: 3302
A63: 62 | B63: 46069 | C63: 11:16 | D63: 46111 | E63: 26200 | F63: 26400 | G63: 25200 | H63: 25000 | I63: 65 | J63: 46094 | K63: TIME | L63: -92 | M63: -5981 | N63: 15 DTE on Sunday - rolled to prior trading day
A64: 63 | B64: 46125 | C64: 11:16 | D64: 46168 | E64: 24700 | F64: 24900 | G64: 23100 | H64: 22900 | I64: 65 | J64: 46153 | K64: TIME | L64: 52 | M64: 3380
A65: 64 | B65: 46160 | C65: 11:16 | D65: 46203 | E65: 24300 | F65: 24500 | G65: 22800 | H65: 22600 | I65: 65 | J65: 46185 | K65: TARGET | L65: 63 | M65: 4096
A66: 65 | B66: 46188 | C66: 11:16 | D66: 46231 | E66: 24600 | F66: 24800 | G66: 23500 | H66: 23300 | I66: 65 | J66: 46216 | K66: TIME | L66: 41.2 | M66: 2678
A67: 66 | B67: 46216 | C67: 11:16 | D67: 46259 | E67: 24800 | F67: 25000 | G67: 23700 | H67: 23500 | I67: 65 | J67: 46244 | K67: TIME | L67: 32.7 | M67: 2126
A68: 67 | B68: 46251 | C68: 11:16 | D68: 46294 | E68: 24900 | F68: 25100 | G68: 24000 | H68: 23800 | I68: 65 | J68: 46276 | K68: TIME | L68: -54 | M68: -3509 | N68: exit time blank in export; 11-Sep-26 user-confirmed (14-Sep holiday)
